[32m2024-02-25 23:40:00 -0300[0m - dagster - [34mDEBUG[0m - all_assets - 5c0f2e8b-88fb-4e34-bbfe-73b95b771601 - 133690 - LOGS_CAPTURED - Started capturing logs in process (pid: 133690).
[32m2024-02-25 23:40:00 -0300[0m - dagster - [34mDEBUG[0m - all_assets - 5c0f2e8b-88fb-4e34-bbfe-73b95b771601 - 133690 - training_data - STEP_START - Started execution of step "training_data".
[32m2024-02-25 23:40:00 -0300[0m - dagster - [34mERROR[0m - [31mall_assets - 5c0f2e8b-88fb-4e34-bbfe-73b95b771601 - 133690 - training_data - STEP_FAILURE - Execution of step "training_data" failed.

dagster._core.errors.DagsterExecutionStepExecutionError: Error occurred while executing op "training_data"::

TypeError: unhashable type: 'Output'

Stack Trace:
  File "/home/antonio/anaconda3/envs/dagster-mlops/lib/python3.9/site-packages/dagster/_core/execution/plan/utils.py", line 54, in op_execution_error_boundary
    yield
  File "/home/antonio/anaconda3/envs/dagster-mlops/lib/python3.9/site-packages/dagster/_utils/__init__.py", line 461, in iterate_with_context
    next_output = next(iterator)
  File "/home/antonio/anaconda3/envs/dagster-mlops/lib/python3.9/site-packages/dagster/_core/execution/plan/compute_generator.py", line 131, in _coerce_op_compute_fn_to_iterator
    result = invoke_compute_fn(
  File "/home/antonio/anaconda3/envs/dagster-mlops/lib/python3.9/site-packages/dagster/_core/execution/plan/compute_generator.py", line 125, in invoke_compute_fn
    return fn(context, **args_to_pass) if context_arg_provided else fn(**args_to_pass)
  File "/home/antonio/Desktop/Recommender_movie_system/movies_dagster/movies_dagster/assets/extract/__init__.py", line 82, in training_data
    metadata={
[0m
