[32m2024-02-25 19:34:09 -0300[0m - dagster - [34mDEBUG[0m - all_assets - 7681fd1d-329e-4138-99c8-a3b07bd0afc4 - 517762 - LOGS_CAPTURED - Started capturing logs in process (pid: 517762).
[32m2024-02-25 19:34:09 -0300[0m - dagster - [34mDEBUG[0m - all_assets - 7681fd1d-329e-4138-99c8-a3b07bd0afc4 - 517762 - training_data - STEP_START - Started execution of step "training_data".
[32m2024-02-25 19:34:09 -0300[0m - dagster - [34mDEBUG[0m - all_assets - 7681fd1d-329e-4138-99c8-a3b07bd0afc4 - 517762 - training_data - STEP_OUTPUT - Yielded output "result" of type "Any". (Type check passed).
[32m2024-02-25 19:34:09 -0300[0m - dagster - [34mERROR[0m - [31mall_assets - 7681fd1d-329e-4138-99c8-a3b07bd0afc4 - 517762 - training_data - STEP_FAILURE - Execution of step "training_data" failed.

dagster._core.errors.DagsterExecutionHandleOutputError: Error occurred while handling output "result" of step "training_data"::

ValueError: Unsupported object type <class 'tuple'> for DbIOManager.

Stack Trace:
  File "/home/antonio/anaconda3/envs/dagster-mlops/lib/python3.9/site-packages/dagster/_core/execution/plan/utils.py", line 54, in op_execution_error_boundary
    yield
  File "/home/antonio/anaconda3/envs/dagster-mlops/lib/python3.9/site-packages/dagster/_utils/__init__.py", line 461, in iterate_with_context
    next_output = next(iterator)
  File "/home/antonio/anaconda3/envs/dagster-mlops/lib/python3.9/site-packages/dagster/_core/execution/plan/execute_step.py", line 722, in _gen_fn
    gen_output = output_manager.handle_output(output_context, output.value)
  File "/home/antonio/Desktop/Recommender_movie_system/movies_dagster/movies_dagster/db_io_manager.py", line 22, in handle_output
    raise ValueError(f"Unsupported object type {type(obj)} for DbIOManager.")
[0m
