[32m2024-02-25 23:49:10 -0300[0m - dagster - [34mDEBUG[0m - __ASSET_JOB - 8ca1776c-ff77-470a-8209-d890706dcf68 - 147013 - LOGS_CAPTURED - Started capturing logs in process (pid: 147013).
[32m2024-02-25 23:49:10 -0300[0m - dagster - [34mDEBUG[0m - __ASSET_JOB - 8ca1776c-ff77-470a-8209-d890706dcf68 - 147013 - training_data - STEP_START - Started execution of step "training_data".
[32m2024-02-25 23:49:10 -0300[0m - dagster - [34mERROR[0m - [31m__ASSET_JOB - 8ca1776c-ff77-470a-8209-d890706dcf68 - 147013 - training_data - STEP_FAILURE - Execution of step "training_data" failed.

dagster._core.errors.DagsterExecutionStepExecutionError: Error occurred while executing op "training_data"::

psycopg2.OperationalError: could not translate host name "('localhost'" to address: Name or service not known
could not translate host name ")" to address: Name or service not known


Stack Trace:
  File "/home/antonio/anaconda3/envs/dagster-mlops/lib/python3.9/site-packages/dagster/_core/execution/plan/utils.py", line 54, in op_execution_error_boundary
    yield
  File "/home/antonio/anaconda3/envs/dagster-mlops/lib/python3.9/site-packages/dagster/_utils/__init__.py", line 461, in iterate_with_context
    next_output = next(iterator)
  File "/home/antonio/Desktop/Recommender_movie_system/movies_dagster/movies_dagster/assets/extract/__init__.py", line 80, in training_data
    conn = psycopg2.connect(
  File "/home/antonio/anaconda3/envs/dagster-mlops/lib/python3.9/site-packages/psycopg2/__init__.py", line 122, in connect
    conn = _connect(dsn, connection_factory=connection_factory, **kwasync)
[0m
